Workbook

Sheet ConsolidadoLoa27_ATIVIDADES
A1: secretaria | B1: unidade | C1: funcao | D1: subfuncao | E1: programa | F1: acao | G1: natureza | H1: Programática_LOA | I1: secretaria | J1: unidade | K1: funcao | L1: subfuncao | M1: programa | N1: acao | O1: natureza | P1: desc_sub | Q1: processo | R1: valor | S1: Peça Orçamentária
A2: 02 | B2: 001 | C2: 04 | D2: 122 | E2: 0001 | F2: 2.011 | G2: 3.3.90.30.00 | H2: =_xlfn.CONCAT(A2,".",B2,".",C2,".",D2,".",E2,".",F2,".",G2) -> 02.001.04.122.0001.2.011.3.3.90.30.00 | I2: 02 - GABINETE DO PREFEITO | J2: 001-CHEFIA DE GABINETE | K2: 4-ADMINISTRAÇÃO | L2: 122-ADMINISTRAÇÃO GERAL | M2: 0001-Administração e Coordenação Geral​ | N2: 2.011-Manutenção de Equipamentos Públicos | O2: 3.3.90.30.00-MATERIAL DE CONSUMO | P2: GÁS ENGARRAFADO | R2: 2500 | S2: LOA
A3: 02 | B3: 001 | C3: 04 | D3: 122 | E3: 0001 | F3: 2.011 | G3: 3.3.90.30.00 | H3: =_xlfn.CONCAT(A3,".",B3,".",C3,".",D3,".",E3,".",F3,".",G3) -> 02.001.04.122.0001.2.011.3.3.90.30.00 | I3: 02 - GABINETE DO PREFEITO | J3: 001-CHEFIA DE GABINETE | K3: 4-ADMINISTRAÇÃO | L3: 122-ADMINISTRAÇÃO GERAL | M3: 0001-Administração e Coordenação Geral​ | N3: 2.011-Manutenção de Equipamentos Públicos | O3: 3.3.90.30.00-MATERIAL DE CONSUMO | P3: MATERIAL DE COPA E COZINHA | R3: 36000 | S3: LOA
A4: 02 | B4: 001 | C4: 04 | D4: 122 | E4: 0001 | F4: 2.011 | G4: 3.3.90.30.00 | H4: =_xlfn.CONCAT(A4,".",B4,".",C4,".",D4,".",E4,".",F4,".",G4) -> 02.001.04.122.0001.2.011.3.3.90.30.00 | I4: 02 - GABINETE DO PREFEITO | J4: 001-CHEFIA DE GABINETE | K4: 4-ADMINISTRAÇÃO | L4: 122-ADMINISTRAÇÃO GERAL | M4: 0001-Administração e Coordenação Geral​ | N4: 2.011-Manutenção de Equipamentos Públicos | O4: 3.3.90.30.00-MATERIAL DE CONSUMO | P4: MATERIAL DE LIMPEZA E PRODUTOS DE HIGIENIZAÇÃO | R4: 12000 | S4: LOA
A5: 02 | B5: 001 | C5: 04 | D5: 122 | E5: 0001 | F5: 2.011 | G5: 3.3.90.30.00 | H5: =_xlfn.CONCAT(A5,".",B5,".",C5,".",D5,".",E5,".",F5,".",G5) -> 02.001.04.122.0001.2.011.3.3.90.30.00 | I5: 02 - GABINETE DO PREFEITO | J5: 001-CHEFIA DE GABINETE | K5: 4-ADMINISTRAÇÃO | L5: 122-ADMINISTRAÇÃO GERAL | M5: 0001-Administração e Coordenação Geral​ | N5: 2.011-Manutenção de Equipamentos Públicos | O5: 3.3.90.30.00-MATERIAL DE CONSUMO | P5: MATERIAL DE EXPEDIENTE | R5: 6500 | S5: LOA
A6: 02 | B6: 001 | C6: 04 | D6: 122 | E6: 0001 | F6: 2.011 | G6: 3.3.90.39.00 | H6: =_xlfn.CONCAT(A6,".",B6,".",C6,".",D6,".",E6,".",F6,".",G6) -> 02.001.04.122.0001.2.011.3.3.90.39.00 | I6: 02 - GABINETE DO PREFEITO | J6: 001-CHEFIA DE GABINETE | K6: 4-ADMINISTRAÇÃO | L6: 122-ADMINISTRAÇÃO GERAL | M6: 0001-Administração e Coordenação Geral​ | N6: 2.011-Manutenção de Equipamentos Públicos | O6: 3.3.90.39.00-OUTROS SERVIÇOS DE TERCEIROS - PESSOA JURÍDICA | P6: MANUTENÇÃO E CONSERVAÇÃO DE BENS IMÓVEIS | R6: 15000 | S6: LOA
A7: 02 | B7: 001 | C7: 04 | D7: 122 | E7: 0001 | F7: 2.011 | G7: 3.1.71.70.00 | H7: =_xlfn.CONCAT(A7,".",B7,".",C7,".",D7,".",E7,".",F7,".",G7) -> 02.001.04.122.0001.2.011.3.1.71.70.00 | I7: 02 - GABINETE DO PREFEITO | J7: 001-CHEFIA DE GABINETE | K7: 4-ADMINISTRAÇÃO | L7: 122-ADMINISTRAÇÃO GERAL | M7: 0001-Administração e Coordenação Geral​ | N7: 2.011-Manutenção de Equipamentos Públicos | O7: 3.1.71.70.00-RATEIO PELA PARTICIPAÇÃO EM CONSÓRCIO PÚBLICO | P7: RATEIO PELA PARTICIPAÇÃO EM CONSÓRCIO PÚBLICO | R7: 434527.81 | S7: LOA
A8: 02 | B8: 001 | C8: 04 | D8: L | E8: 0001 | F8: 2.011 | G8: 3.3.71.70.00 | H8: =_xlfn.CONCAT(A8,".",B8,".",C8,".",D8,".",E8,".",F8,".",G8) -> 02.001.04.L.0001.2.011.3.3.71.70.00 | I8: 02 - GABINETE DO PREFEITO | J8: 001-CHEFIA DE GABINETE | K8: 4-ADMINISTRAÇÃO | L8: 122-ADMINISTRAÇÃO GERAL | M8: 0001-Administração e Coordenação Geral​ | N8: 2.011-Manutenção de Equipamentos Públicos | O8: 3.3.71.70.00-RATEIO PELA PARTICIPAÇÃO EM CONSÓRCIO PÚBLICO | P8: RATEIO PELA PARTICIPAÇÃO EM CONSÓRCIO PÚBLICO | R8: 2511423.4 | S8: LOA
A9: 02 | B9: 001 | C9: 04 | D9: 122 | E9: 0001 | F9: 2.011 | G9: 3.3.90.30.00 | H9: =_xlfn.CONCAT(A9,".",B9,".",C9,".",D9,".",E9,".",F9,".",G9) -> 02.001.04.122.0001.2.011.3.3.90.30.00 | I9: 02 - GABINETE DO PREFEITO | J9: 001-CHEFIA DE GABINETE | K9: 4-ADMINISTRAÇÃO | L9: 122-ADMINISTRAÇÃO GERAL | M9: 0001-Administração e Coordenação Geral​ | N9: 2.011-Manutenção de Equipamentos Públicos | O9: 3.3.90.30.00-MATERIAL DE CONSUMO | P9: MATERIAL PARA MANUTENÇÃO DE BENS IMÓVEIS | R9: 15000 | S9: LOA
A10: 02 | B10: 001 | C10: 04 | D10: 122 | E10: 0001 | F10: 2.011 | G10: 4.4.50.52.00 | H10: =_xlfn.CONCAT(A10,".",B10,".",C10,".",D10,".",E10,".",F10,".",G10) -> 02.001.04.122.0001.2.011.4.4.50.52.00 | I10: 02 - GABINETE DO PREFEITO | J10: 001-CHEFIA DE GABINETE | K10: 4-ADMINISTRAÇÃO | L10: 122-ADMINISTRAÇÃO GERAL | M10: 0001-Administração e Coordenação Geral​ | N10: 2.011-Manutenção de Equipamentos Públicos | O10: 4.4.50.52.00-EQUIPAMENTOS E MATERIAL PERMANENTE | P10: APARELHOS E UTENSÍLIOS DOMÉSTICOS | R10: 22500 | S10: LOA
A11: 02 | B11: 001 | C11: 04 | D11: 122 | E11: 0001 | F11: 2.011 | G11: 3.3.90.39.00 | H11: =_xlfn.CONCAT(A11,".",B11,".",C11,".",D11,".",E11,".",F11,".",G11) -> 02.001.04.122.0001.2.011.3.3.90.39.00 | I11: 02 - GABINETE DO PREFEITO | J11: 001-CHEFIA DE GABINETE | K11: 4-ADMINISTRAÇÃO | L11: 122-ADMINISTRAÇÃO GERAL | M11: 0001-Administração e Coordenação Geral​ | N11: 2.011-Manutenção de Equipamentos Públicos | O11: 3.3.90.39.00-OUTROS SERVIÇOS DE TERCEIROS - PESSOA JURÍDICA | P11: ASSINATURAS DE PERIÓDICOS E ANUIDADES | R11: 318414 | S11: LOA
A12: 02 | B12: 001 | C12: 04 | D12: 122 | E12: 0001 | F12: 2.011 | G12: 3.3.90.39.00 | H12: =_xlfn.CONCAT(A12,".",B12,".",C12,".",D12,".",E12,".",F12,".",G12) -> 02.001.04.122.0001.2.011.3.3.90.39.00 | I12: 02 - GABINETE DO PREFEITO | J12: 001-CHEFIA DE GABINETE | K12: 4-ADMINISTRAÇÃO | L12: 122-ADMINISTRAÇÃO GERAL | M12: 0001-Administração e Coordenação Geral​ | N12: 2.011-Manutenção de Equipamentos Públicos | O12: 3.3.90.39.00-OUTROS SERVIÇOS DE TERCEIROS - PESSOA JURÍDICA | P12: MANUTENÇÃO E CONSERVAÇÃO DE VEÍCULOS | R12: 15000 | S12: LOA
A13: 02 | B13: 001 | C13: 04 | D13: 122 | E13: 0001 | F13: 2.011 | G13: 3.3.90.39.00 | H13: =_xlfn.CONCAT(A13,".",B13,".",C13,".",D13,".",E13,".",F13,".",G13) -> 02.001.04.122.0001.2.011.3.3.90.39.00 | I13: 02 - GABINETE DO PREFEITO | J13: 001-CHEFIA DE GABINETE | K13: 4-ADMINISTRAÇÃO | L13: 122-ADMINISTRAÇÃO GERAL | M13: 0001-Administração e Coordenação Geral​ | N13: 2.011-Manutenção de Equipamentos Públicos | O13: 3.3.90.39.00-OUTROS SERVIÇOS DE TERCEIROS - PESSOA JURÍDICA | P13: LOCAÇÃO BENS MÓVEIS DE OUTRAS NATUREZAS E INTANGÍVEIS | R13: 45000 | S13: LOA
... A24: 02 | B24: 001 | C24: 04 | D24: 122 | E24: 0001 | F24: 2.011 | G24: 3.3.90.39.00 | H24: =_xlfn.CONCAT(A24,".",B24,".",C24,".",D24,".",E24,".",F24,".",G24) -> 02.001.04.122.0001.2.011.3.3.90.39.00 | I24: 02 - GABINETE DO PREFEITO | J24: 001-CHEFIA DE GABINETE | K24: 4-ADMINISTRAÇÃO | L24: 122-ADMINISTRAÇÃO GERAL | M24: 0001-Administração e Coordenação Geral​ | N24: 2.011-Manutenção de Equipamentos Públicos | O24: 3.3.90.39.00-OUTROS SERVIÇOS DE TERCEIROS - PESSOA JURÍDICA | P24: FORNECIMENTO DE ALIMENTAÇÃO | R24: 1 | S24: LOA
A25: 04 | B25: 001 | C25: 04 | D25: 126 | E25: 0002 | F25: 2.007 | G25: 3.3.90.40.00 | H25: =_xlfn.CONCAT(A25,".",B25,".",C25,".",D25,".",E25,".",F25,".",G25) -> 04.001.04.126.0002.2.007.3.3.90.40.00 | I25: 04 - SECRETARIA DE FINANÇAS | J25: 001-GABINETE DA SECRETARIA DE FINANÇAS | K25: 4-ADMINISTRAÇÃO | L25: 126-TECNOLOGIA DA INFORMATIZAÇÃO | M25: 0002-Governo Inteligente, Aberto e Inovador​ | N25: 2.007-Ampliação e Manutenção de Sistemas de Inteligência, Fiscalização e Tecnologia | O25: 3.3.90.40.00-SERVIÇOS DE TECNOLOGIA DA INFORMAÇÃO E COMUNICAÇÃO - PESSOA JURÍDICA | P25: OUTROS SERVIÇOS DE TECNOLOGIA DA INFORMAÇÃO E COMUNICAÇÃO - PESSOA JURÍDICA | Q25: 961/2024 | R25: 7642566.6 | S25: LOA
A26: 04 | B26: 001 | C26: 04 | D26: 126 | E26: 0002 | F26: 2.007 | G26: 3.3.90.40.00 | H26: =_xlfn.CONCAT(A26,".",B26,".",C26,".",D26,".",E26,".",F26,".",G26) -> 04.001.04.126.0002.2.007.3.3.90.40.00 | I26: 04 - SECRETARIA DE FINANÇAS | J26: 001-GABINETE DA SECRETARIA DE FINANÇAS | K26: 4-ADMINISTRAÇÃO | L26: 126-TECNOLOGIA DA INFORMATIZAÇÃO | M26: 0002-Governo Inteligente, Aberto e Inovador​ | N26: 2.007-Ampliação e Manutenção de Sistemas de Inteligência, Fiscalização e Tecnologia | O26: 3.3.90.40.00-SERVIÇOS DE TECNOLOGIA DA INFORMAÇÃO E COMUNICAÇÃO - PESSOA JURÍDICA | P26: MATERIAL PARA MANUTENÇÃO DE BENS IMÓVEIS | Q26: 24087/2021 | R26: 32880000 | S26: LOA
A27: 04 | B27: 001 | C27: 04 | D27: 126 | E27: 0002 | F27: 2.007 | G27: 3.3.90.39.00 | H27: =_xlfn.CONCAT(A27,".",B27,".",C27,".",D27,".",E27,".",F27,".",G27) -> 04.001.04.126.0002.2.007.3.3.90.39.00 | I27: 04 - SECRETARIA DE FINANÇAS | J27: 001-GABINETE DA SECRETARIA DE FINANÇAS | K27: 4-ADMINISTRAÇÃO | L27: 126-TECNOLOGIA DA INFORMATIZAÇÃO | M27: 0002-Governo Inteligente, Aberto e Inovador​ | N27: 2.007-Ampliação e Manutenção de Sistemas de Inteligência, Fiscalização e Tecnologia | O27: 3.3.90.39.00-OUTROS SERVIÇOS DE TERCEIROS - PESSOA JURÍDICA | P27: ASSINATURAS DE PERIÓDICOS E ANUIDADES | Q27: 9534/2022 | R27: 100000 | S27: LOA
A28: 04 | B28: 001 | C28: 04 | D28: 122 | E28: 0001 | F28: 2.011 | G28: 3.3.90.39.00 | H28: =_xlfn.CONCAT(A28,".",B28,".",C28,".",D28,".",E28,".",F28,".",G28) -> 04.001.04.122.0001.2.011.3.3.90.39.00 | I28: 04 - SECRETARIA DE FINANÇAS | J28: 001-GABINETE DA SECRETARIA DE FINANÇAS | K28: 4-ADMINISTRAÇÃO | L28: 122-ADMINISTRAÇÃO GERAL | M28: 0001-Administração e Coordenação Geral​ | N28: 2.011-Manutenção de Equipamentos Públicos | O28: 3.3.90.39.00-OUTROS SERVIÇOS DE TERCEIROS - PESSOA JURÍDICA | P28: OUTROS SERVIÇOS DE TERCEIRO PESSOA JURÍDICA - PAGAMENTO ANTECIPADO | Q28: não tem (certificado digital) | R28: 16500 | S28: LOA
A29: 04 | B29: 001 | C29: 04 | D29: 122 | E29: 0001 | F29: 2.011 | G29: 3.3.90.39.00 | H29: =_xlfn.CONCAT(A29,".",B29,".",C29,".",D29,".",E29,".",F29,".",G29) -> 04.001.04.122.0001.2.011.3.3.90.39.00 | I29: 04 - SECRETARIA DE FINANÇAS | J29: 001-GABINETE DA SECRETARIA DE FINANÇAS | K29: 4-ADMINISTRAÇÃO | L29: 122-ADMINISTRAÇÃO GERAL | M29: 0001-Administração e Coordenação Geral​ | N29: 2.011-Manutenção de Equipamentos Públicos | O29: 3.3.90.39.00-OUTROS SERVIÇOS DE TERCEIROS - PESSOA JURÍDICA | P29: MANUTENÇÃO E CONSERVAÇÃO DE BENS MÓVEIS DE OUTRAS NATUREZAS | Q29: não tem (adiantamentos) | R29: 20000 | S29: LOA
A30: 04 | B30: 001 | C30: 04 | D30: 122 | E30: 0001 | F30: 2.011 | G30: 3.3.90.93.00 | H30: =_xlfn.CONCAT(A30,".",B30,".",C30,".",D30,".",E30,".",F30,".",G30) -> 04.001.04.122.0001.2.011.3.3.90.93.00 | I30: 04 - SECRETARIA DE FINANÇAS | J30: 001-GABINETE DA SECRETARIA DE FINANÇAS | K30: 4-ADMINISTRAÇÃO | L30: 122-ADMINISTRAÇÃO GERAL | M30: 0001-Administração e Coordenação Geral​ | N30: 2.011-Manutenção de Equipamentos Públicos | O30: 3.3.90.93.00-INDENIZAÇÕES E RESTITUIÇÕES | P30: RESTITUIÇÕES | Q30: não tem (ressarcimentos) | R30: 10000 | S30: LOA
A31: 04 | B31: 001 | C31: 04 | D31: 122 | E31: 0002 | F31: 2.011 | G31: 3.3.90.33.00 | H31: =_xlfn.CONCAT(A31,".",B31,".",C31,".",D31,".",E31,".",F31,".",G31) -> 04.001.04.122.0002.2.011.3.3.90.33.00 | I31: 04 - SECRETARIA DE FINANÇAS | J31: 001-GABINETE DA SECRETARIA DE FINANÇAS | K31: 4-ADMINISTRAÇÃO | L31: 122-ADMINISTRAÇÃO GERAL | M31: 0002-Governo Inteligente, Aberto e Inovador​ | N31: 2.011-Manutenção de Equipamentos Públicos | O31: 3.3.90.33.00-PASSAGENS E DESPESAS COM LOCOMOÇÃO | Q31: Ata 77/2025 (viagens) | R31: 40000 | S31: LOA
A32: 04 | B32: 001 | C32: 04 | D32: 122 | E32: 0001 | F32: 2.011 | G32: 3.3.90.39.00 | H32: =_xlfn.CONCAT(A32,".",B32,".",C32,".",D32,".",E32,".",F32,".",G32) -> 04.001.04.122.0001.2.011.3.3.90.39.00 | I32: 04 - SECRETARIA DE FINANÇAS | J32: 001-GABINETE DA SECRETARIA DE FINANÇAS | K32: 4-ADMINISTRAÇÃO | L32: 122-ADMINISTRAÇÃO GERAL | M32: 0001-Administração e Coordenação Geral​ | N32: 2.011-Manutenção de Equipamentos Públicos | O32: 3.3.90.39.00-OUTROS SERVIÇOS DE TERCEIROS - PESSOA JURÍDICA | P32: MANUTENÇÃO E CONSERVAÇÃO DE BENS MÓVEIS DE OUTRAS NATUREZAS | Q32: não tem (ar condicionado) | R32: 25000 | S32: LOA
A33: 04 | B33: 001 | C33: 04 | D33: 122 | E33: 0001 | F33: 2.011 | G33: 3.3.90.39.00 | H33: =_xlfn.CONCAT(A33,".",B33,".",C33,".",D33,".",E33,".",F33,".",G33) -> 04.001.04.122.0001.2.011.3.3.90.39.00 | I33: 04 - SECRETARIA DE FINANÇAS | J33: 001-GABINETE DA SECRETARIA DE FINANÇAS | K33: 4-ADMINISTRAÇÃO | L33: 122-ADMINISTRAÇÃO GERAL | M33: 0001-Administração e Coordenação Geral​ | N33: 2.011-Manutenção de Equipamentos Públicos | O33: 3.3.90.39.00-OUTROS SERVIÇOS DE TERCEIROS - PESSOA JURÍDICA | P33: MANUTENÇÃO E CONSERVAÇÃO DE BENS MÓVEIS DE OUTRAS NATUREZAS | Q33: não tem (veículos) | R33: 10000 | S33: LOA
A34: 04 | B34: 001 | C34: 04 | D34: 122 | E34: 0001 | F34: 2.011 | G34: 3.3.90.39.00 | H34: =_xlfn.CONCAT(A34,".",B34,".",C34,".",D34,".",E34,".",F34,".",G34) -> 04.001.04.122.0001.2.011.3.3.90.39.00 | I34: 04 - SECRETARIA DE FINANÇAS | J34: 001-GABINETE DA SECRETARIA DE FINANÇAS | K34: 4-ADMINISTRAÇÃO | L34: 122-ADMINISTRAÇÃO GERAL | M34: 0001-Administração e Coordenação Geral​ | N34: 2.011-Manutenção de Equipamentos Públicos | O34: 3.3.90.39.00-OUTROS SERVIÇOS DE TERCEIROS - PESSOA JURÍDICA | P34: MANUTENÇÃO E CONSERVAÇÃO DE BENS MÓVEIS DE OUTRAS NATUREZAS | Q34: não tem (bebedouros) | R34: 2000 | S34: LOA
A35: 04 | B35: 001 | C35: 04 | D35: 122 | E35: 0001 | F35: 2.011 | G35: 3.3.90.39.00 | H35: =_xlfn.CONCAT(A35,".",B35,".",C35,".",D35,".",E35,".",F35,".",G35) -> 04.001.04.122.0001.2.011.3.3.90.39.00 | I35: 04 - SECRETARIA DE FINANÇAS | J35: 001-GABINETE DA SECRETARIA DE FINANÇAS | K35: 4-ADMINISTRAÇÃO | L35: 122-ADMINISTRAÇÃO GERAL | M35: 0001-Administração e Coordenação Geral​ | N35: 2.011-Manutenção de Equipamentos Públicos | O35: 3.3.90.39.00-OUTROS SERVIÇOS DE TERCEIROS - PESSOA JURÍDICA | P35: MANUTENÇÃO E CONSERVAÇÃO DE BENS MÓVEIS DE OUTRAS NATUREZAS | Q35: não tem (hidraúlica, elétrica...) | R35: 5000 | S35: LOA
A36: 04 | B36: 001 | C36: 04 | D36: 122 | E36: 0001 | F36: 2.011 | G36: 4.4.90.52.00 | H36: =_xlfn.CONCAT(A36,".",B36,".",C36,".",D36,".",E36,".",F36,".",G36) -> 04.001.04.122.0001.2.011.4.4.90.52.00 | I36: 04 - SECRETARIA DE FINANÇAS | J36: 001-GABINETE DA SECRETARIA DE FINANÇAS | K36: 4-ADMINISTRAÇÃO | L36: 122-ADMINISTRAÇÃO GERAL | M36: 0001-Administração e Coordenação Geral​ | N36: 2.011-Manutenção de Equipamentos Públicos | O36: 4.4.90.52.00-EQUIPAMENTOS E MATERIAL PERMANENTE | P36: MÁQUINAS, UTENSÍLIOS E EQUIPAMENTOS DIVERSOS | Q36: não tem (ar condicionado) | R36: 40000 | S36: LOA
A37: 04 | B37: 001 | C37: 04 | D37: 122 | E37: 0001 | F37: 2.011 | G37: 3.3.90.30.00 | H37: =_xlfn.CONCAT(A37,".",B37,".",C37,".",D37,".",E37,".",F37,".",G37) -> 04.001.04.122.0001.2.011.3.3.90.30.00 | I37: 04 - SECRETARIA DE FINANÇAS | J37: 001-GABINETE DA SECRETARIA DE FINANÇAS | K37: 4-ADMINISTRAÇÃO | L37: 122-ADMINISTRAÇÃO GERAL | M37: 0001-Administração e Coordenação Geral​ | N37: 2.011-Manutenção de Equipamentos Públicos | O37: 3.3.90.30.00-MATERIAL DE CONSUMO | P37: MATERIAL DE COPA E COZINHA | Q37: Ata 146/2026 | R37: 16000 | S37: LOA
A38: 04 | B38: 001 | C38: 04 | D38: 122 | E38: 0001 | F38: 2.011 | G38: 3.3.90.30.00 | H38: =_xlfn.CONCAT(A38,".",B38,".",C38,".",D38,".",E38,".",F38,".",G38) -> 04.001.04.122.0001.2.011.3.3.90.30.00 | I38: 04 - SECRETARIA DE FINANÇAS | J38: 001-GABINETE DA SECRETARIA DE FINANÇAS | K38: 4-ADMINISTRAÇÃO | L38: 122-ADMINISTRAÇÃO GERAL | M38: 0001-Administração e Coordenação Geral​ | N38: 2.011-Manutenção de Equipamentos Públicos | O38: 3.3.90.30.00-MATERIAL DE CONSUMO | P38: MATERIAL DE COPA E COZINHA | Q38: Ata 66/2025 | R38: 2000 | S38: LOA
A39: 04 | B39: 001 | C39: 04 | D39: 122 | E39: 0001 | F39: 2.011 | G39: 3.3.90.30.00 | H39: =_xlfn.CONCAT(A39,".",B39,".",C39,".",D39,".",E39,".",F39,".",G39) -> 04.001.04.122.0001.2.011.3.3.90.30.00 | I39: 04 - SECRETARIA DE FINANÇAS | J39: 001-GABINETE DA SECRETARIA DE FINANÇAS | K39: 4-ADMINISTRAÇÃO | L39: 122-ADMINISTRAÇÃO GERAL | M39: 0001-Administração e Coordenação Geral​ | N39: 2.011-Manutenção de Equipamentos Públicos | O39: 3.3.90.30.00-MATERIAL DE CONSUMO | P39: MATERIAL DE LIMPEZA E PRODUTOS DE HIGIENIZAÇÃO | Q39: Ata 28 e 48/2026 | R39: 10000 | S39: LOA
A40: 04 | B40: 001 | C40: 04 | D40: 122 | E40: 0001 | F40: 2.011 | G40: 3.3.90.30.00 | H40: =_xlfn.CONCAT(A40,".",B40,".",C40,".",D40,".",E40,".",F40,".",G40) -> 04.001.04.122.0001.2.011.3.3.90.30.00 | I40: 04 - SECRETARIA DE FINANÇAS | J40: 001-GABINETE DA SECRETARIA DE FINANÇAS | K40: 4-ADMINISTRAÇÃO | L40: 122-ADMINISTRAÇÃO GERAL | M40: 0001-Administração e Coordenação Geral​ | N40: 2.011-Manutenção de Equipamentos Públicos | O40: 3.3.90.30.00-MATERIAL DE CONSUMO | P40: MATERIAL DE LIMPEZA E PRODUTOS DE HIGIENIZAÇÃO | Q40: Ata 93/2025 | R40: 28000 | S40: LOA
A41: 04 | B41: 001 | C41: 04 | D41: 122 | E41: 0001 | F41: 2.011 | G41: 3.3.90.30.00 | H41: =_xlfn.CONCAT(A41,".",B41,".",C41,".",D41,".",E41,".",F41,".",G41) -> 04.001.04.122.0001.2.011.3.3.90.30.00 | I41: 04 - SECRETARIA DE FINANÇAS | J41: 001-GABINETE DA SECRETARIA DE FINANÇAS | K41: 4-ADMINISTRAÇÃO | L41: 122-ADMINISTRAÇÃO GERAL | M41: 0001-Administração e Coordenação Geral​ | N41: 2.011-Manutenção de Equipamentos Públicos | O41: 3.3.90.30.00-MATERIAL DE CONSUMO | P41: MATERIAL ELÉTRICO E ELETRÔNICO | Q41: Ata 105 e 107/2025 | R41: 5000 | S41: LOA
A42: 04 | B42: 001 | C42: 04 | D42: 122 | E42: 0001 | F42: 2.011 | G42: 3.3.90.30.00 | H42: =_xlfn.CONCAT(A42,".",B42,".",C42,".",D42,".",E42,".",F42,".",G42) -> 04.001.04.122.0001.2.011.3.3.90.30.00 | I42: 04 - SECRETARIA DE FINANÇAS | J42: 001-GABINETE DA SECRETARIA DE FINANÇAS | K42: 4-ADMINISTRAÇÃO | L42: 122-ADMINISTRAÇÃO GERAL | M42: 0001-Administração e Coordenação Geral​ | N42: 2.011-Manutenção de Equipamentos Públicos | O42: 3.3.90.30.00-MATERIAL DE CONSUMO | P42: MATERIAL PARA MANUTENÇÃO DE VEÍCULOS | Q42: não tem (veículos) | R42: 10000 | S42: LOA
A43: 05 | B43: 001 | C43: 04 | D43: 122 | E43: 0001 | F43: 2.011 | G43: 3.3.90.30.00 | H43: =_xlfn.CONCAT(A43,".",B43,".",C43,".",D43,".",E43,".",F43,".",G43) -> 05.001.04.122.0001.2.011.3.3.90.30.00 | I43: 05 - PROCURADORIA GERAL DO MUNICÍPIO | J43: 001-GABINETE DA PROCURADORIA GERAL DO MUNICÍPIO | K43: 4-ADMINISTRAÇÃO | L43: 122-ADMINISTRAÇÃO GERAL | M43: 0001-Administração e Coordenação Geral​ | N43: 2.011-Manutenção de Equipamentos Públicos | O43: 3.3.90.30.00-MATERIAL DE CONSUMO | P43: MATERIAL DE COPA E COZINHA | R43: 25000 | S43: LOA
A44: 05 | B44: 001 | C44: 04 | D44: 122 | E44: 0001 | F44: 2.011 | G44: 3.3.90.30.00 | H44: =_xlfn.CONCAT(A44,".",B44,".",C44,".",D44,".",E44,".",F44,".",G44) -> 05.001.04.122.0001.2.011.3.3.90.30.00 | I44: 05 - PROCURADORIA GERAL DO MUNICÍPIO | J44: 001-GABINETE DA PROCURADORIA GERAL DO MUNICÍPIO | K44: 4-ADMINISTRAÇÃO | L44: 122-ADMINISTRAÇÃO GERAL | M44: 0001-Administração e Coordenação Geral​ | N44: 2.011-Manutenção de Equipamentos Públicos | O44: 3.3.90.30.00-MATERIAL DE CONSUMO | P44: MATERIAL DE EXPEDIENTE | R44: 25000 | S44: LOA
A45: 05 | B45: 001 | C45: 04 | D45: 122 | E45: 0001 | F45: 2.011 | G45: 3.3.90.30.00 | H45: =_xlfn.CONCAT(A45,".",B45,".",C45,".",D45,".",E45,".",F45,".",G45) -> 05.001.04.122.0001.2.011.3.3.90.30.00 | I45: 05 - PROCURADORIA GERAL DO MUNICÍPIO | J45: 001-GABINETE DA PROCURADORIA GERAL DO MUNICÍPIO | K45: 4-ADMINISTRAÇÃO | L45: 122-ADMINISTRAÇÃO GERAL | M45: 0001-Administração e Coordenação Geral​ | N45: 2.011-Manutenção de Equipamentos Públicos | O45: 3.3.90.30.00-MATERIAL DE CONSUMO | P45: MATERIAL DE LIMPEZA E PRODUTOS DE HIGIENIZAÇÃO | R45: 35000 | S45: LOA
A46: 05 | B46: 001 | C46: 04 | D46: 122 | E46: 0001 | F46: 2.011 | G46: 3.3.90.39.00 | H46: =_xlfn.CONCAT(A46,".",B46,".",C46,".",D46,".",E46,".",F46,".",G46) -> 05.001.04.122.0001.2.011.3.3.90.39.00 | I46: 05 - PROCURADORIA GERAL DO MUNICÍPIO | J46: 001-GABINETE DA PROCURADORIA GERAL DO MUNICÍPIO | K46: 4-ADMINISTRAÇÃO | L46: 122-ADMINISTRAÇÃO GERAL | M46: 0001-Administração e Coordenação Geral​ | N46: 2.011-Manutenção de Equipamentos Públicos | O46: 3.3.90.39.00-OUTROS SERVIÇOS DE TERCEIROS - PESSOA JURÍDICA | P46: OUTROS SERVIÇOS DE TERCEIROS - PESSOA JURÍDICA | Q46: Pagamento de Perito | R46: 100000 | S46: LOA
A47: 05 | B47: 001 | C47: 04 | D47: 122 | E47: 0001 | F47: 2.011 | G47: 3.3.90.39.00 | H47: =_xlfn.CONCAT(A47,".",B47,".",C47,".",D47,".",E47,".",F47,".",G47) -> 05.001.04.122.0001.2.011.3.3.90.39.00 | I47: 05 - PROCURADORIA GERAL DO MUNICÍPIO | J47: 001-GABINETE DA PROCURADORIA GERAL DO MUNICÍPIO | K47: 4-ADMINISTRAÇÃO | L47: 122-ADMINISTRAÇÃO GERAL | M47: 0001-Administração e Coordenação Geral​ | N47: 2.011-Manutenção de Equipamentos Públicos | O47: 3.3.90.39.00-OUTROS SERVIÇOS DE TERCEIROS - PESSOA JURÍDICA | P47: OUTROS SERVIÇOS DE TERCEIROS - PESSOA JURÍDICA | Q47: Locação de Veículos | R47: 44279 | S47: LOA
A48: 05 | B48: 001 | C48: 04 | D48: 122 | E48: 0001 | F48: 2.011 | G48: 3.3.90.39.00 | H48: =_xlfn.CONCAT(A48,".",B48,".",C48,".",D48,".",E48,".",F48,".",G48) -> 05.001.04.122.0001.2.011.3.3.90.39.00 | I48: 05 - PROCURADORIA GERAL DO MUNICÍPIO | J48: 001-GABINETE DA PROCURADORIA GERAL DO MUNICÍPIO | K48: 4-ADMINISTRAÇÃO | L48: 122-ADMINISTRAÇÃO GERAL | M48: 0001-Administração e Coordenação Geral​ | N48: 2.011-Manutenção de Equipamentos Públicos | O48: 3.3.90.39.00-OUTROS SERVIÇOS DE TERCEIROS - PESSOA JURÍDICA | P48: OUTROS SERVIÇOS DE TERCEIROS - PESSOA JURÍDICA | Q48: 1221/2025 | R48: 27784.02 | S48: LOA
A49: 05 | B49: 001 | C49: 04 | D49: 122 | E49: 0001 | F49: 2.011 | G49: 3.3.90.39.00 | H49: =_xlfn.CONCAT(A49,".",B49,".",C49,".",D49,".",E49,".",F49,".",G49) -> 05.001.04.122.0001.2.011.3.3.90.39.00 | I49: 05 - PROCURADORIA GERAL DO MUNICÍPIO | J49: 001-GABINETE DA PROCURADORIA GERAL DO MUNICÍPIO | K49: 4-ADMINISTRAÇÃO | L49: 122-ADMINISTRAÇÃO GERAL | M49: 0001-Administração e Coordenação Geral​ | N49: 2.011-Manutenção de Equipamentos Públicos | O49: 3.3.90.39.00-OUTROS SERVIÇOS DE TERCEIROS - PESSOA JURÍDICA | P49: OUTROS SERVIÇOS DE TERCEIROS - PESSOA JURÍDICA | Q49: 7925/2021 | R49: 15000 | S49: LOA
A50: 05 | B50: 001 | C50: 04 | D50: 122 | E50: 0001 | F50: 2.011 | G50: 3.3.90.39.00 | H50: =_xlfn.CONCAT(A50,".",B50,".",C50,".",D50,".",E50,".",F50,".",G50) -> 05.001.04.122.0001.2.011.3.3.90.39.00 | I50: 05 - PROCURADORIA GERAL DO MUNICÍPIO | J50: 001-GABINETE DA PROCURADORIA GERAL DO MUNICÍPIO | K50: 4-ADMINISTRAÇÃO | L50: 122-ADMINISTRAÇÃO GERAL | M50: 0001-Administração e Coordenação Geral​ | N50: 2.011-Manutenção de Equipamentos Públicos | O50: 3.3.90.39.00-OUTROS SERVIÇOS DE TERCEIROS - PESSOA JURÍDICA | P50: OUTROS SERVIÇOS DE TERCEIROS - PESSOA JURÍDICA | Q50: 1227/2024 | R50: 49472 | S50: LOA
...

Sheet LDO 2027
A1: PROGRAMÁTICA | B1: VALOR FINAL PLDO 27 | C1: DS_INICIATIVA | D1: Programática LDO | E1: Secretaria | F1: Ação
A2: 01.001.01.031.0003.1.003.3.3.90.39.01.110.0000 | B2: 2000000 | C2: Construção da Nova Sede da Câmara | D2: =_xlfn.CONCAT(LEFT(A2,34),".00") -> 01.001.01.031.0003.1.003.3.3.90.39.00 | E2: =VLOOKUP(LEFT(A2,2),ConsolidadoLoa27_ATIVIDADES!A:I,9,0) -> 01- CMO | F2: =MID(A2,20,5) -> 1.003 | G2: =RIGHT(A2,11) -> 01.110.0000
A3: 01.001.01.031.0003.1.003.3.3.90.92.01.110.0000 | B3: 1 | C3: Construção da Nova Sede da Câmara | D3: =_xlfn.CONCAT(LEFT(A3,34),".00") -> 01.001.01.031.0003.1.003.3.3.90.92.00 | E3: =VLOOKUP(LEFT(A3,2),ConsolidadoLoa27_ATIVIDADES!A:I,9,0) -> 01- CMO | F3: =MID(A3,20,5) -> 1.003 | G3: =RIGHT(A3,11) -> 01.110.0000
A4: 01.001.01.031.0003.1.003.3.3.90.93.01.110.0000 | B4: 1 | C4: Construção da Nova Sede da Câmara | D4: =_xlfn.CONCAT(LEFT(A4,34),".00") -> 01.001.01.031.0003.1.003.3.3.90.93.00 | E4: =VLOOKUP(LEFT(A4,2),ConsolidadoLoa27_ATIVIDADES!A:I,9,0) -> 01- CMO | F4: =MID(A4,20,5) -> 1.003 | G4: =RIGHT(A4,11) -> 01.110.0000
A5: 01.001.01.031.0003.1.003.4.4.90.51.01.110.0000 | B5: 1000000 | C5: Construção da Nova Sede da Câmara | D5: =_xlfn.CONCAT(LEFT(A5,34),".00") -> 01.001.01.031.0003.1.003.4.4.90.51.00 | E5: =VLOOKUP(LEFT(A5,2),ConsolidadoLoa27_ATIVIDADES!A:I,9,0) -> 01- CMO | F5: =MID(A5,20,5) -> 1.003 | G5: =RIGHT(A5,11) -> 01.110.0000
A6: 01.001.01.031.0003.1.003.4.4.90.52.01.110.0000 | B6: 3500000 | C6: Construção da Nova Sede da Câmara | D6: =_xlfn.CONCAT(LEFT(A6,34),".00") -> 01.001.01.031.0003.1.003.4.4.90.52.00 | E6: =VLOOKUP(LEFT(A6,2),ConsolidadoLoa27_ATIVIDADES!A:I,9,0) -> 01- CMO | F6: =MID(A6,20,5) -> 1.003 | G6: =RIGHT(A6,11) -> 01.110.0000
A7: 01.001.01.031.0003.1.003.4.4.90.92.01.110.0000 | B7: 1 | C7: Construção da Nova Sede da Câmara | D7: =_xlfn.CONCAT(LEFT(A7,34),".00") -> 01.001.01.031.0003.1.003.4.4.90.92.00 | E7: =VLOOKUP(LEFT(A7,2),ConsolidadoLoa27_ATIVIDADES!A:I,9,0) -> 01- CMO | F7: =MID(A7,20,5) -> 1.003 | G7: =RIGHT(A7,11) -> 01.110.0000
A8: 01.001.01.031.0003.2.042.3.3.90.14.01.110.0000 | B8: 1 | C8: Manutenção das Atividades Legislativas | D8: =_xlfn.CONCAT(LEFT(A8,34),".00") -> 01.001.01.031.0003.2.042.3.3.90.14.00 | E8: =VLOOKUP(LEFT(A8,2),ConsolidadoLoa27_ATIVIDADES!A:I,9,0) -> 01- CMO | F8: =MID(A8,20,5) -> 2.042 | G8: =RIGHT(A8,11) -> 01.110.0000
A9: 01.001.01.031.0003.2.042.3.3.90.30.01.110.0000 | B9: 1575000 | C9: Manutenção das Atividades Legislativas | D9: =_xlfn.CONCAT(LEFT(A9,34),".00") -> 01.001.01.031.0003.2.042.3.3.90.30.00 | E9: =VLOOKUP(LEFT(A9,2),ConsolidadoLoa27_ATIVIDADES!A:I,9,0) -> 01- CMO | F9: =MID(A9,20,5) -> 2.042 | G9: =RIGHT(A9,11) -> 01.110.0000
A10: 01.001.01.031.0003.2.042.3.3.90.32.01.110.0000 | B10: 1 | C10: Manutenção das Atividades Legislativas | D10: =_xlfn.CONCAT(LEFT(A10,34),".00") -> 01.001.01.031.0003.2.042.3.3.90.32.00 | E10: =VLOOKUP(LEFT(A10,2),ConsolidadoLoa27_ATIVIDADES!A:I,9,0) -> 01- CMO | F10: =MID(A10,20,5) -> 2.042 | G10: =RIGHT(A10,11) -> 01.110.0000
A11: 01.001.01.031.0003.2.042.3.3.90.33.01.110.0000 | B11: 1 | C11: Manutenção das Atividades Legislativas | D11: =_xlfn.CONCAT(LEFT(A11,34),".00") -> 01.001.01.031.0003.2.042.3.3.90.33.00 | E11: =VLOOKUP(LEFT(A11,2),ConsolidadoLoa27_ATIVIDADES!A:I,9,0) -> 01- CMO | F11: =MID(A11,20,5) -> 2.042 | G11: =RIGHT(A11,11) -> 01.110.0000
A12: 01.001.01.031.0003.2.042.3.3.90.35.01.110.0000 | B12: 1 | C12: Manutenção das Atividades Legislativas | D12: =_xlfn.CONCAT(LEFT(A12,34),".00") -> 01.001.01.031.0003.2.042.3.3.90.35.00 | E12: =VLOOKUP(LEFT(A12,2),ConsolidadoLoa27_ATIVIDADES!A:I,9,0) -> 01- CMO | F12: =MID(A12,20,5) -> 2.042 | G12: =RIGHT(A12,11) -> 01.110.0000
A13: 01.001.01.031.0003.2.042.3.3.90.37.01.110.0000 | B13: 1 | C13: Manutenção das Atividades Legislativas | D13: =_xlfn.CONCAT(LEFT(A13,34),".00") -> 01.001.01.031.0003.2.042.3.3.90.37.00 | E13: =VLOOKUP(LEFT(A13,2),ConsolidadoLoa27_ATIVIDADES!A:I,9,0) -> 01- CMO | F13: =MID(A13,20,5) -> 2.042 | G13: =RIGHT(A13,11) -> 01.110.0000
... A279: 08.001.12.122.0001.2.008.3.3.90.39.01.200.0000 | B279: 493440 | C279: Estagiários - Ensino Superior SED - Taxa | D279: =_xlfn.CONCAT(LEFT(A279,34),".00") -> 08.001.12.122.0001.2.008.3.3.90.39.00 | E279: =VLOOKUP(LEFT(A279,2),ConsolidadoLoa27_ATIVIDADES!A:I,9,0) -> 08 - SECRETARIA DE EDUCAÇÃO | F279: =MID(A279,20,5) -> 2.008 | G279: =RIGHT(A279,11) -> 01.200.0000
A280: 08.001.12.122.0001.2.008.3.3.90.48.01.110.0000 | C280: Estagiários Ensino Superior - SED | D280: =_xlfn.CONCAT(LEFT(A280,34),".00") -> 08.001.12.122.0001.2.008.3.3.90.48.00 | E280: =VLOOKUP(LEFT(A280,2),ConsolidadoLoa27_ATIVIDADES!A:I,9,0) -> 08 - SECRETARIA DE EDUCAÇÃO | F280: =MID(A280,20,5) -> 2.008 | G280: =RIGHT(A280,11) -> 01.110.0000
A281: 08.001.12.122.0001.2.008.3.3.90.48.01.200.0000 | B281: 16964195 | C281: Estagiários Ensino Superior - SED | D281: =_xlfn.CONCAT(LEFT(A281,34),".00") -> 08.001.12.122.0001.2.008.3.3.90.48.00 | E281: =VLOOKUP(LEFT(A281,2),ConsolidadoLoa27_ATIVIDADES!A:I,9,0) -> 08 - SECRETARIA DE EDUCAÇÃO | F281: =MID(A281,20,5) -> 2.008 | G281: =RIGHT(A281,11) -> 01.200.0000
A282: 08.001.12.122.0001.2.011.3.3.50.39.08.110.0000 | B282: 0 | C282: Emenda Impositiva - Josias da Juco - E.E José Ribeiro de Souza | D282: =_xlfn.CONCAT(LEFT(A282,34),".00") -> 08.001.12.122.0001.2.011.3.3.50.39.00 | E282: =VLOOKUP(LEFT(A282,2),ConsolidadoLoa27_ATIVIDADES!A:I,9,0) -> 08 - SECRETARIA DE EDUCAÇÃO | F282: =MID(A282,20,5) -> 2.011 | G282: =RIGHT(A282,11) -> 08.110.0000
A283: 08.001.12.122.0001.2.011.3.3.90.30.01.110.0000 | B283: 103910 | C283: Copa e Cozinha | D283: =_xlfn.CONCAT(LEFT(A283,34),".00") -> 08.001.12.122.0001.2.011.3.3.90.30.00 | E283: =VLOOKUP(LEFT(A283,2),ConsolidadoLoa27_ATIVIDADES!A:I,9,0) -> 08 - SECRETARIA DE EDUCAÇÃO | F283: =MID(A283,20,5) -> 2.011 | G283: =RIGHT(A283,11) -> 01.110.0000
A284: 08.001.12.122.0001.2.011.3.3.90.30.01.110.0000 | B284: 373606.33 | C284: Higiene e Limpeza | D284: =_xlfn.CONCAT(LEFT(A284,34),".00") -> 08.001.12.122.0001.2.011.3.3.90.30.00 | E284: =VLOOKUP(LEFT(A284,2),ConsolidadoLoa27_ATIVIDADES!A:I,9,0) -> 08 - SECRETARIA DE EDUCAÇÃO | F284: =MID(A284,20,5) -> 2.011 | G284: =RIGHT(A284,11) -> 01.110.0000
A285: 08.001.12.122.0001.2.011.3.3.90.30.01.110.0000 | B285: 62346 | C285: Manutenção de Veículos | D285: =_xlfn.CONCAT(LEFT(A285,34),".00") -> 08.001.12.122.0001.2.011.3.3.90.30.00 | E285: =VLOOKUP(LEFT(A285,2),ConsolidadoLoa27_ATIVIDADES!A:I,9,0) -> 08 - SECRETARIA DE EDUCAÇÃO | F285: =MID(A285,20,5) -> 2.011 | G285: =RIGHT(A285,11) -> 01.110.0000
A286: 08.001.12.122.0001.2.011.3.3.90.30.01.110.0000 | B286: 51955 | C286: Sistema de Climatização - Materiais | D286: =_xlfn.CONCAT(LEFT(A286,34),".00") -> 08.001.12.122.0001.2.011.3.3.90.30.00 | E286: =VLOOKUP(LEFT(A286,2),ConsolidadoLoa27_ATIVIDADES!A:I,9,0) -> 08 - SECRETARIA DE EDUCAÇÃO | F286: =MID(A286,20,5) -> 2.011 | G286: =RIGHT(A286,11) -> 01.110.0000
A287: 08.001.12.122.0001.2.011.3.3.90.30.01.110.0000 | B287: 6700 | C287: Materiais de Expediente | D287: =_xlfn.CONCAT(LEFT(A287,34),".00") -> 08.001.12.122.0001.2.011.3.3.90.30.00 | E287: =VLOOKUP(LEFT(A287,2),ConsolidadoLoa27_ATIVIDADES!A:I,9,0) -> 08 - SECRETARIA DE EDUCAÇÃO | F287: =MID(A287,20,5) -> 2.011 | G287: =RIGHT(A287,11) -> 01.110.0000
A288: 08.001.12.122.0001.2.011.3.3.90.30.01.200.0000 | B288: 169947 | C288: Materiais de Expediente | D288: =_xlfn.CONCAT(LEFT(A288,34),".00") -> 08.001.12.122.0001.2.011.3.3.90.30.00 | E288: =VLOOKUP(LEFT(A288,2),ConsolidadoLoa27_ATIVIDADES!A:I,9,0) -> 08 - SECRETARIA DE EDUCAÇÃO | F288: =MID(A288,20,5) -> 2.011 | G288: =RIGHT(A288,11) -> 01.200.0000
A289: 08.001.12.122.0001.2.011.3.3.90.39.01.110.0000 | B289: 610990.8 | C289: Contas de Consumo | D289: =_xlfn.CONCAT(LEFT(A289,34),".00") -> 08.001.12.122.0001.2.011.3.3.90.39.00 | E289: =VLOOKUP(LEFT(A289,2),ConsolidadoLoa27_ATIVIDADES!A:I,9,0) -> 08 - SECRETARIA DE EDUCAÇÃO | F289: =MID(A289,20,5) -> 2.011 | G289: =RIGHT(A289,11) -> 01.110.0000
A290: 08.001.12.122.0001.2.011.3.3.90.39.01.110.0000 | B290: 31173 | C290: Manutenção de Veículos | D290: =_xlfn.CONCAT(LEFT(A290,34),".00") -> 08.001.12.122.0001.2.011.3.3.90.39.00 | E290: =VLOOKUP(LEFT(A290,2),ConsolidadoLoa27_ATIVIDADES!A:I,9,0) -> 08 - SECRETARIA DE EDUCAÇÃO | F290: =MID(A290,20,5) -> 2.011 | G290: =RIGHT(A290,11) -> 01.110.0000
A291: 08.001.12.122.0001.2.011.3.3.90.39.01.110.0000 | B291: 51955 | C291: Sistema de Climatização - Serviços | D291: =_xlfn.CONCAT(LEFT(A291,34),".00") -> 08.001.12.122.0001.2.011.3.3.90.39.00 | E291: =VLOOKUP(LEFT(A291,2),ConsolidadoLoa27_ATIVIDADES!A:I,9,0) -> 08 - SECRETARIA DE EDUCAÇÃO | F291: =MID(A291,20,5) -> 2.011 | G291: =RIGHT(A291,11) -> 01.110.0000
A292: 08.001.12.122.0001.2.011.3.3.90.39.01.110.0000 | B292: 12469.2 | C292: Taxas, Tarifas, Multas e Anuidade | D292: =_xlfn.CONCAT(LEFT(A292,34),".00") -> 08.001.12.122.0001.2.011.3.3.90.39.00 | E292: =VLOOKUP(LEFT(A292,2),ConsolidadoLoa27_ATIVIDADES!A:I,9,0) -> 08 - SECRETARIA DE EDUCAÇÃO | F292: =MID(A292,20,5) -> 2.011 | G292: =RIGHT(A292,11) -> 01.110.0000
... A2374: 99.999.99.999.9999.9.999.9.9.99.99.08.804.0000 | B2374: 24000000 | C2374: Emenda Impositiva - Saúde | D2374: =_xlfn.CONCAT(LEFT(A2374,34),".00") -> 99.999.99.999.9999.9.999.9.9.99.99.00 | E2374: =VLOOKUP(LEFT(A2374,2),ConsolidadoLoa27_ATIVIDADES!A:I,9,0) -> PMO - RC | F2374: =MID(A2374,20,5) -> 9.999 | G2374: =RIGHT(A2374,11) -> 08.804.0000
A2375: =D2375 -> 02.001.04.122.0001.2.011.4.4.50.52.00 | B2375: 0 | C2375: Sem previsão na LDO | D2375: 02.001.04.122.0001.2.011.4.4.50.52.00 | E2375: =VLOOKUP(LEFT(A2375,2),ConsolidadoLoa27_ATIVIDADES!A:I,9,0) -> 02 - GABINETE DO PREFEITO | F2375: =MID(A2375,20,5) -> 2.011 | G2375: =RIGHT(A2375,11) -> .4.50.52.00
A2376: =D2376 -> 02.012.04.122.0001.2.011.3.3.90.39.00 | B2376: 0 | C2376: Sem previsão na LDO | D2376: 02.012.04.122.0001.2.011.3.3.90.39.00 | E2376: =VLOOKUP(LEFT(A2376,2),ConsolidadoLoa27_ATIVIDADES!A:I,9,0) -> 02 - GABINETE DO PREFEITO | F2376: =MID(A2376,20,5) -> 2.011 | G2376: =RIGHT(A2376,11) -> .3.90.39.00
A2377: =D2377 -> 02.012.04.122.0001.2.011.4.4.50.52.00 | B2377: 0 | C2377: Sem previsão na LDO | D2377: 02.012.04.122.0001.2.011.4.4.50.52.00 | E2377: =VLOOKUP(LEFT(A2377,2),ConsolidadoLoa27_ATIVIDADES!A:I,9,0) -> 02 - GABINETE DO PREFEITO | F2377: =MID(A2377,20,5) -> 2.011 | G2377: =RIGHT(A2377,11) -> .4.50.52.00
A2378: =D2378 -> 04.001.04.122.0001.2.011.3.3.90.93.00 | B2378: 0 | C2378: Sem previsão na LDO | D2378: 04.001.04.122.0001.2.011.3.3.90.93.00 | E2378: =VLOOKUP(LEFT(A2378,2),ConsolidadoLoa27_ATIVIDADES!A:I,9,0) -> 04 - SECRETARIA DE FINANÇAS | F2378: =MID(A2378,20,5) -> 2.011 | G2378: =RIGHT(A2378,11) -> .3.90.93.00
A2379: =D2379 -> 04.001.04.122.0002.2.011.3.3.90.33.00 | B2379: 0 | C2379: Sem previsão na LDO | D2379: 04.001.04.122.0002.2.011.3.3.90.33.00 | E2379: =VLOOKUP(LEFT(A2379,2),ConsolidadoLoa27_ATIVIDADES!A:I,9,0) -> 04 - SECRETARIA DE FINANÇAS | F2379: =MID(A2379,20,5) -> 2.011 | G2379: =RIGHT(A2379,11) -> .3.90.33.00
A2380: =D2380 -> 04.001.04.122.0001.2.011.4.4.90.52.00 | B2380: 0 | C2380: Sem previsão na LDO | D2380: 04.001.04.122.0001.2.011.4.4.90.52.00 | E2380: =VLOOKUP(LEFT(A2380,2),ConsolidadoLoa27_ATIVIDADES!A:I,9,0) -> 04 - SECRETARIA DE FINANÇAS | F2380: =MID(A2380,20,5) -> 2.011 | G2380: =RIGHT(A2380,11) -> .4.90.52.00
A2381: =D2381 -> 05.001.04.122.0001.2.011.4.4.90.52.00 | B2381: 0 | C2381: Sem previsão na LDO | D2381: 05.001.04.122.0001.2.011.4.4.90.52.00 | E2381: =VLOOKUP(LEFT(A2381,2),ConsolidadoLoa27_ATIVIDADES!A:I,9,0) -> 05 - PROCURADORIA GERAL DO MUNICÍPIO | F2381: =MID(A2381,20,5) -> 2.011 | G2381: =RIGHT(A2381,11) -> .4.90.52.00
A2382: =D2382 -> 06.001.04.122.0001.2.011.4.4.90.52.00 | B2382: 0 | C2382: Sem previsão na LDO | D2382: 06.001.04.122.0001.2.011.4.4.90.52.00 | E2382: =VLOOKUP(LEFT(A2382,2),ConsolidadoLoa27_ATIVIDADES!A:I,9,0) -> 06 - SECRETARIA DE ADMINISTRAÇÃO | F2382: =MID(A2382,20,5) -> 2.011 | G2382: =RIGHT(A2382,11) -> .4.90.52.00
A2383: =D2383 -> 06.001.04.122.0001.2.011.3.3.90.92.00 | B2383: 0 | C2383: Sem previsão na LDO | D2383: 06.001.04.122.0001.2.011.3.3.90.92.00 | E2383: =VLOOKUP(LEFT(A2383,2),ConsolidadoLoa27_ATIVIDADES!A:I,9,0) -> 06 - SECRETARIA DE ADMINISTRAÇÃO | F2383: =MID(A2383,20,5) -> 2.011 | G2383: =RIGHT(A2383,11) -> .3.90.92.00
A2384: =D2384 -> 06.001.04.122.0001.2.011.3.3.90.93.00 | B2384: 0 | C2384: Sem previsão na LDO | D2384: 06.001.04.122.0001.2.011.3.3.90.93.00 | E2384: =VLOOKUP(LEFT(A2384,2),ConsolidadoLoa27_ATIVIDADES!A:I,9,0) -> 06 - SECRETARIA DE ADMINISTRAÇÃO | F2384: =MID(A2384,20,5) -> 2.011 | G2384: =RIGHT(A2384,11) -> .3.90.93.00
A2385: =D2385 -> 06.011.04.128.0002.2.003.3.3.90.30.00 | B2385: 0 | C2385: Sem previsão na LDO | D2385: 06.011.04.128.0002.2.003.3.3.90.30.00 | E2385: =VLOOKUP(LEFT(A2385,2),ConsolidadoLoa27_ATIVIDADES!A:I,9,0) -> 06 - SECRETARIA DE ADMINISTRAÇÃO | F2385: =MID(A2385,20,5) -> 2.003 | G2385: =RIGHT(A2385,11) -> .3.90.30.00
A2386: =D2386 -> 06.011.04.128.0002.2.003.3.3.90.40.00 | B2386: 0 | C2386: Sem previsão na LDO | D2386: 06.011.04.128.0002.2.003.3.3.90.40.00 | E2386: =VLOOKUP(LEFT(A2386,2),ConsolidadoLoa27_ATIVIDADES!A:I,9,0) -> 06 - SECRETARIA DE ADMINISTRAÇÃO | F2386: =MID(A2386,20,5) -> 2.003 | G2386: =RIGHT(A2386,11) -> .3.90.40.00
...

Sheet Planilha3
A3: desc_sub | B3: (Tudo)
A4: processo | B4: (Tudo)
A5: acao | B5: (Vários itens)
A7: Soma de valor | D7: Peça Orçamentária
A8: secretaria2 | B8: Programática_LOA | C8: natureza | D8: LDO | E8: LOA | F8: LDO - LOA
A9: 01- CMO | D9: 148065765 | E9: 148065765 | F9: =D9-E9 -> 0
A10: 02 - GABINETE DO PREFEITO | D10: 18874619 | E10: 11899869 | F10: =D10-E10 -> 6974749.8
A11: 04 - SECRETARIA DE FINANÇAS | D11: 62642563 | E11: 75652774 | F11: =D11-E11 -> -13010210
A12: 05 - PROCURADORIA GERAL DO MUNICÍPIO | D12: 33757519 | E12: 35154694 | F12: =D12-E12 -> -1397174.9
A13: 06 - SECRETARIA DE ADMINISTRAÇÃO | D13: 37676638 | E13: 37231192 | F13: =D13-E13 -> 445446.65
A14: 07 - SECRETARIA DE EMPREGO, TRABALHO E RENDA | D14: 57883745 | E14: 26648767 | F14: =D14-E14 -> 31234978
A15: 08 - SECRETARIA DE EDUCAÇÃO | D15: 1.8419565e+09 | E15: 1.9647853e+09 | F15: =D15-E15 -> -1.2282887e+08
A16: 09 - SECRETARIA DA SAÚDE | D16: 1.1882527e+09 | E16: 1.3941639e+09 | F16: =D16-E16 -> -2.0591119e+08
A17: 11 - SECRETARIA DE SERVIÇOS E OBRAS | D17: 4.3866268e+08 | E17: 5.122192e+08 | F17: =D17-E17 -> -73556524
A18: 12 - SECRETARIA DE ESPORTE, RECREAÇÃO E LAZER | D18: 30836077 | E18: 23349507 | F18: =D18-E18 -> 7486570.5
A19: 13 - SECRETARIA DE HABITAÇÃO | D19: 57373716 | E19: 1.0287072e+08 | F19: =D19-E19 -> -45497004
A20: 14 - SECRETARIA DE ASSISTÊNCIA SOCIAL | D20: 1.5334309e+08 | E20: 1.0535109e+08 | F20: =D20-E20 -> 47992001
... A43: Total Geral | D43: 5.7572313e+09 | E43: 6.2331825e+09 | F43: =D43-E43 -> -4.759512e+08

Sheet Planilha1
A1: unidade | C1: funcao | E1: subfuncao | G1: programa | I1: acao | K1: natureza
A2: 001-CHEFIA DE GABINETE | C2: 4-ADMINISTRAÇÃO | E2: 122-ADMINISTRAÇÃO GERAL | G2: 0001-Administração e Coordenação Geral​ | I2: 2.011-Manutenção de Equipamentos Públicos | K2: 3.3.90.30.00-MATERIAL DE CONSUMO
A3: 012-FUNDO ESPECIAL DE MANUTENÇÃO DOS BOMBEIROS | C3: 11-TRABALHO | E3: 126-TECNOLOGIA DA INFORMATIZAÇÃO | G3: 0002-Governo Inteligente, Aberto e Inovador​ | I3: 2.007-Ampliação e Manutenção de Sistemas de Inteligência, Fiscalização e Tecnologia | K3: 3.3.90.39.00-OUTROS SERVIÇOS DE TERCEIROS - PESSOA JURÍDICA
A4: 001-GABINETE DA SECRETARIA DE FINANÇAS | C4: 12-EDUCAÇÃO | E4: 128-FORMAÇÃO DE RECURSOS HUMANOS | G4: 0017-Trabalho, Emprego e Renda​ | I4: 2.003-Qualificação de Servidores e Processos Institucionais | K4: 3.1.71.70.00-RATEIO PELA PARTICIPAÇÃO EM CONSÓRCIO PÚBLICO
A5: 001-GABINETE DA PROCURADORIA GERAL DO MUNICÍPIO | C5: 10-SAÚDE | E5: 334-FOMENTO AO TRABALHO | G5: 0016-Escola para Todos​ | I5: 2.006-Representações Oficiais | K5: 3.3.71.70.00-RATEIO PELA PARTICIPAÇÃO EM CONSÓRCIO PÚBLICO
A6: 001-GABINETE DA SECRETARIA DE ADMINISTRAÇÃO | C6: 15-URBANISMO | E6: 333-EMPREGABILIDADE | G6: 0015-Atenção e Cuidado em Saúde​ | I6: 2.005-Promoção de Eventos, Comunicação e Participação Social | K6: 4.4.50.52.00-EQUIPAMENTOS E MATERIAL PERMANENTE
A7: 011-FUNDO MUNICIPAL DE VALORIZAÇÃO DOS SERVIDORES | C7: 17-SANEAMENTO | E7: 361-ENSINO FUNDAMENTAL | G7: 0014-Gestão em Saúde​ | I7: 1.002-Reforma e Ampliação de Unidades | K7: 3.3.90.40.00-SERVIÇOS DE TECNOLOGIA DA INFORMAÇÃO E COMUNICAÇÃO - PESSOA JURÍDICA
A8: 001-GABINETE DA SECRETARIA DE EMPREGO, TRABALHO E RENDA | C8: 18-GESTÃO AMBIENTAL | E8: 365-EDUCAÇÃO INFANTIL | G8: 0004-Planejamento e Gestão de Políticas Públicas | I8: 2.027-Intermediação Profissional | K8: 3.3.90.93.00-INDENIZAÇÕES E RESTITUIÇÕES
A9: 001-FUNDO MUNICIPAL DO TRABALHO | C9: 27-DESPORTO E LAZER | E9: 364-ENSINO SUPERIOR | G9: 0011-Zeladoria Urbana e Cuidados com a Cidade​ | I9: 2.004-Qualificação Socioprofissional | K9: 3.3.90.33.00-PASSAGENS E DESPESAS COM LOCOMOÇÃO
A10: 001-GABINETE DA SECRETARIA DA EDUCAÇÃO | C10: 16-HABITAÇÃO | E10: 306-ALIMENTAÇÃO E NUTRIÇÃO | G10: 0013-Mobilidade Urbana e Infraestrutura Viária​ | I10: 2.033-Fortalecimento da Economia Criativa e Solidária | K10: 4.4.90.52.00-EQUIPAMENTOS E MATERIAL PERMANENTE
A11: 001-GABINETE DA SECRETARIA DA SAÚDE | C11: 8-ASSISTÊNCIA SOCIAL | E11: 366-EDUCAÇÃO DE JOVENS E ADULTOS | G11: 0007-Meio Ambiente, Sustentabilidade e Bem-Estar Animal​ | I11: 2.025-Auxílio para Inclusão no Mercado de Trabalho | K11: 3.3.90.92.00-DESPESAS DE EXERCÍCIOS ANTERIORES
A12: 010-DIRETORIA GERAL DE URGÊNCIA E EMERGÊNCIA | C12: 13-CULTURA | E12: 367-EDUCAÇÃO ESPECIAL | G12: 0005-Resiliência Urbana​ | I12: 1.003-Implantação de Novas Unidades | K12: 3.3.90.36.00-OUTROS SERVIÇOS DE TERCEIROS - PESSOA FÍSICA
... A15: 008-DIRETORIA GERAL DE ATENÇÃO PRIMÁRIA EM SAÚDE | C15: 14-DIREITOS DA CIDADANIA | E15: 301-ATENÇÃO BÁSICA | G15: 0019-Segurança Alimentar e Combate à Pobreza​ | I15: 2.017-Suporte ao Aluno | K15: 3.3.90.96.00-RESSARCIMENTO DE DESPESAS DE PESSOAL REQUISITADO
A16: 015-DIRETORIA GERAL DA GESTÃO DE SAÚDE | C16: =VLOOKUP(#REF!,$E$1:$T$994,9,0) -> #REF! | E16: 303-SUPORTE PROFILÁTICO E TERAPÊUTICO | G16: 0018-Proteção Social e Garantia de Direitos​ | I16: 2.018-Conectividade e Tecnologia na Educação | K16: 3.3.90.31.00-PREMIAÇÕES CULTURAIS, ARTÍSTICAS, CIENTÍFICAS, DESPORTIVAS E OUTRAS
A17: 012-DEPARTAMENTO DE ASSISTÊNCIA FARMACÊUTICA | E17: 121-PLANEJAMENTO E ORÇAMENTO | G17: 0009-Cultura, Economia Criativa e Patrimônio Histórico​ | I17: 2.019-Ações Pedagógicas Complementares | K17: 3.3.90.48.00 - OUTROS AUXILIOS FINANCEIROS A PESSOAS FISICAS
A18: 001-GABINETE DA SECRETARIA DE SERVIÇOS E OBRAS | E18: 452-SERVIÇOS URBNOS | G18: 0008-Empreendedorismo, Negócios e Turismo​ | I18: 2.020-Transporte de Alunos | K18: 3.3.90.32.00-MATERIAL, BEM OU SERVIÇO PARA DISTRIBUIÇÃO GRATUITA
A19: 014-FUNDO MUNICIPAL DE MANUTENÇÃO DE VELÓRIOS | E19: 451-INFRA-ESTRUTURA URBANA | G19: 0006-Segurança Pública e Fiscalização Inteligente​ | I19: 2.022-Parcerias para Criação de Vagas | K19: 4.4.50.39.00-OUTROS SERVIÇOS DE TERCEIROS - PESSOA JURÍDICA
A20: 001-GABINETE DA SECRETARIA DE ESPORTE, RECREAÇÃO E LAZER | E20: 452-SERVIÇOS URBANOS | G20: =#REF! -> #REF! | I20: 2.023-Gestão Compartilhada de Equipamentos Públicos | K20: 3.3.50.85.00-CONTRATO DE GESTÃO
A21: 001-GABINETE DA SECRETARIA DE HABITAÇÃO | E21: 544-RECURSOS HÍDRICOS | I21: 2.013-Manutenção de Equipamentos Públicos - Atenção Especializada
A22: 008-FUNDO MUNICIPAL DE POLÍTICA URBANA E HABITACIONAL | E22: 543-RECUPERAÇÃO DE ÁREAS DEGRADADAS | I22: 2.014-Manutenção de Equipamentos Públicos - Atenção Hospitalar e Urgência e Emergência | K22: 4.5.90.62.00-AQUISIÇÃO DE PRODUTOS PARA REVENDA
A23: 001-GABINETE DA SECRETARIA DE ASSISTÊNCIA SOCIAL | E23: 811-DESPORTO DE RENDIMENTO | I23: 2.012-Manutenção de Equipamentos Públicos - Atenção Primária | K23: 4.4.71.70.00-RATEIO PELA PARTICIPAÇÃO EM CONSÓRCIO PÚBLICO
A24: 005-FUNDO MUNICIPAL DE ASSISTÊNCIA SOCIAL | E24: 812-DESPORTO COMUNITÁRIO | I24: 2.026-Residências e Internações Compulsórias | K24: 4.4.50.51.00-OBRAS E INSTALAÇÕES
A25: 007-DEPARTAMENTO DE PROTEÇÃO SOCIAL BÁSICA | E25: 482-HABITAÇÃO URBANA | I25: 1.001-Estudos, Pesquisas, Planos e Projetos | K25: 3.3.90.48.00-OUTROS AUXÍLIOS FINANCEIROS A PESSOA FÍSICA
A26: 008-DEPARTAMENTO DE PROTEÇÃO SOCIAL ESPECIAL | E26: 245-SERVIÇOS SOCIOASSISTENCIAIS | I26: 2.034-Manutenção da Infraestrutura Viária | K26: 3.3.90.91.00-SENTENÇAS JUDICIAIS
A27: 001-GABINETE DA CULTURA | E27: 246-SEGURANÇA DE RENDA | I27: 1.006-Desenvolvimento da Infraestrutura Viária | K27: 3.3.90.35.00-SERVIÇOS DE CONSULTORIA
A28: 001-GABINETE DA SECRETARIA DE TECNOLOGIA, INOVAÇÃO E DESENVOLVIMENTO ECONÔMICO | E28: 241-ASSISTÊNCIA AO IDOSO ASSISTÊNCIA À PESSOA IDOSA | I28: 2.038-Iluminação Pública | K28: =VLOOKUP(#REF!,$L$1:$T$994,9,0) -> #REF!
A29: 001-GABINETE DA SECRETARIA DE MEIO AMBIENTE E RECURSOS HÍDRICOS | E29: 392-DIFUSÃO CULTURAL | I29: 2.039-Limpeza Urbana e Gestão de Resíduos Sólidos
A30: 003-FUNDO MUNICIPAL DE MEIO AMBIENTE | E30: 541-PRESERVAÇÃO E CONSERVAÇÃO AMBIENTAL | I30: 2.035-Manutenção e Serviços de Drenagem Urbana
A31: 002-RECURSOS SOB A SUPERVISÃO DA SECRETARIA DE ADMINISTRAÇÃO | E31: 422-DIREITOS INDIVIDUAIS, COLETIVOS E DIFUSOS | I31: 2.037-Ampliação e Manutenção de Áreas Verdes
A32: 001-RECURSOS SOB A SUPERVISÃO DA SECRETARIA DE FINANÇAS | E32: 453-TRANSPORTES COLETIVOS URBANOS | I32: 2.032-Iniciação Esportiva
A33: 003-RECURSOS SOB SUPERVISÃO DA SECRETARIA DE TECNOLOGIA, INOVAÇÃO E DESENVOLVIMENTO ECONÔMICO | E33: 181-POLICIAMENTO | I33: 2.030-Apoio ao Esporte de Alto Rendimento
A34: 001-GABINETE DA SECRETARIA DE TRANSPORTE E DA MOBILIDADE URBANA | E34: 242-ASSISTÊNCIA AO PORTADOR DE DEFICIÊNCIA ASSISTÊNCIA À PESSOA COM DEFICIÊNCIA | I34: 2.028-Disseminação de Atividades Culturais e Esportivas Decentralizadas
A35: 005-FUNDO MUNICIPAL DE TRÂNSITO | E35: 391-PATRIMÔNIO HISTÓRICO, ARTÍSTICO E ARQUEOLÓGICO | I35: 2.031-Esporte Amador
A36: 001-GABINETE DA SECRETARIA DE SEGURANÇA E CONTROLE URBANO | E36: 182-DEFESA CIVIL | I36: 1.009-Urbanização de Favelas e Comunidades
A37: 001-GABINETE DA SECRETARIA DE COMUNICAÇÃO | E37: 244-ASSISTÊNCIA COMUNITÁRIA | I37: 1.010-Requalificação de Favelas e Comunidades
A38: 001-GABINETE DA SECRETARIA DE PLANEJAMENTO E GESTÃO | E38: =VLOOKUP(#REF!,$G$1:$T$994,9,0) -> #REF! | I38: 1.014-Recuperação de Conjuntos Habitacionais
A39: 001-GABINETE DA CONTROLADORIA GERAL DO MUNICÍPIO | I39: 1.011-Regularização Fundiária de Assentamentos Precários, Loteamentos e Conjuntos Habitacionais
A40: 001-GABINETE DA SECRETARIA DE GOVERNO | I40: 2.024-Distribuição de Alimentos e Benefícios para as Famílias em Situação de Vulnerabilidade
A41: 007-FUNDO MUNICIPAL DE POLÍTICAS SOBRE DROGAS | I41: 2.015-Manutenção de Equipamentos Públicos - Proteção Básica
A42: 001-GABINETE DA SECRETARIA EXECUTIVA DA PESSOA COM DEFICIÊNCIA | I42: 2.016-Manutenção de Equipamentos Públicos - Proteção Especial
...

Sheet Programática que não tem na LDO
A1: secretaria | B1: unidade | C1: funcao | D1: subfuncao | E1: programa | F1: acao | G1: natureza | H1: Programática_LOA | I1: secretaria | J1: unidade | K1: funcao | L1: subfuncao | M1: programa | N1: acao | O1: natureza | P1: desc_sub | Q1: processo | R1: valor
A2: 02 | B2: 001 | C2: 04 | D2: 122 | E2: 0001 | F2: 2.011 | G2: 4.4.50.52.00 | H2: 02.001.04.122.0001.2.011.4.4.50.52.00 | I2: 02 - GABINETE DO PREFEITO | J2: 001-CHEFIA DE GABINETE | K2: 4-ADMINISTRAÇÃO | L2: 122-ADMINISTRAÇÃO GERAL | M2: 0001-Administração e Coordenação Geral​ | N2: 2.011-Manutenção de Equipamentos Públicos | O2: 4.4.50.52.00-EQUIPAMENTOS E MATERIAL PERMANENTE | P2: APARELHOS E UTENSÍLIOS DOMÉSTICOS | R2: 22500 | S2: Não tem o Cód. na LDO
A3: 02 | B3: 012 | C3: 04 | D3: 122 | E3: 0001 | F3: 2.011 | G3: 3.3.90.39.00 | H3: 02.012.04.122.0001.2.011.3.3.90.39.00 | I3: 02 - GABINETE DO PREFEITO | J3: 012-FUNDO ESPECIAL DE MANUTENÇÃO DOS BOMBEIROS | K3: 4-ADMINISTRAÇÃO | L3: 122-ADMINISTRAÇÃO GERAL | M3: 0001-Administração e Coordenação Geral​ | N3: 2.011-Manutenção de Equipamentos Públicos | O3: 3.3.90.39.00-OUTROS SERVIÇOS DE TERCEIROS - PESSOA JURÍDICA | P3: MANUTENÇÃO E CONSERVAÇÃO DE VEÍCULOS | R3: 20000 | S3: Não tem o Cód. na LDO
A4: 02 | B4: 012 | C4: 04 | D4: 122 | E4: 0001 | F4: 2.011 | G4: 4.4.50.52.00 | H4: 02.012.04.122.0001.2.011.4.4.50.52.00 | I4: 02 - GABINETE DO PREFEITO | J4: 012-FUNDO ESPECIAL DE MANUTENÇÃO DOS BOMBEIROS | K4: 4-ADMINISTRAÇÃO | L4: 122-ADMINISTRAÇÃO GERAL | M4: 0001-Administração e Coordenação Geral​ | N4: 2.011-Manutenção de Equipamentos Públicos | O4: 4.4.50.52.00-EQUIPAMENTOS E MATERIAL PERMANENTE | P4: APARELHOS E UTENSÍLIOS DOMÉSTICOS | R4: 3000 | S4: Não tem o Cód. na LDO
A5: 04 | B5: 001 | C5: 04 | D5: 122 | E5: 0001 | F5: 2.011 | G5: 3.3.90.93.00 | H5: 04.001.04.122.0001.2.011.3.3.90.93.00 | I5: 04 - SECRETARIA DE FINANÇAS | J5: 001-GABINETE DA SECRETARIA DE FINANÇAS | K5: 4-ADMINISTRAÇÃO | L5: 122-ADMINISTRAÇÃO GERAL | M5: 0001-Administração e Coordenação Geral​ | N5: 2.011-Manutenção de Equipamentos Públicos | O5: 3.3.90.93.00-INDENIZAÇÕES E RESTITUIÇÕES | P5: RESTITUIÇÕES | Q5: não tem (ressarcimentos) | R5: 10000 | S5: Não tem o Cód. na LDO
A6: 04 | B6: 001 | C6: 04 | D6: 122 | E6: 0002 | F6: 2.011 | G6: 3.3.90.33.00 | H6: 04.001.04.122.0002.2.011.3.3.90.33.00 | I6: 04 - SECRETARIA DE FINANÇAS | J6: 001-GABINETE DA SECRETARIA DE FINANÇAS | K6: 4-ADMINISTRAÇÃO | L6: 122-ADMINISTRAÇÃO GERAL | M6: 0002-Governo Inteligente, Aberto e Inovador​ | N6: 2.011-Manutenção de Equipamentos Públicos | O6: 3.3.90.33.00-PASSAGENS E DESPESAS COM LOCOMOÇÃO | Q6: Ata 77/2025 (viagens) | R6: 40000 | S6: Não tem o Cód. na LDO
A7: 04 | B7: 001 | C7: 04 | D7: 122 | E7: 0001 | F7: 2.011 | G7: 4.4.90.52.00 | H7: 04.001.04.122.0001.2.011.4.4.90.52.00 | I7: 04 - SECRETARIA DE FINANÇAS | J7: 001-GABINETE DA SECRETARIA DE FINANÇAS | K7: 4-ADMINISTRAÇÃO | L7: 122-ADMINISTRAÇÃO GERAL | M7: 0001-Administração e Coordenação Geral​ | N7: 2.011-Manutenção de Equipamentos Públicos | O7: 4.4.90.52.00-EQUIPAMENTOS E MATERIAL PERMANENTE | P7: MÁQUINAS, UTENSÍLIOS E EQUIPAMENTOS DIVERSOS | Q7: não tem (ar condicionado) | R7: 40000 | S7: Não tem o Cód. na LDO
A8: 05 | B8: 001 | C8: 04 | D8: 122 | E8: 0001 | F8: 2.011 | G8: 4.4.90.52.00 | H8: 05.001.04.122.0001.2.011.4.4.90.52.00 | I8: 05 - PROCURADORIA GERAL DO MUNICÍPIO | J8: 001-GABINETE DA PROCURADORIA GERAL DO MUNICÍPIO | K8: 4-ADMINISTRAÇÃO | L8: 122-ADMINISTRAÇÃO GERAL | M8: 0001-Administração e Coordenação Geral​ | N8: 2.011-Manutenção de Equipamentos Públicos | O8: 4.4.90.52.00-EQUIPAMENTOS E MATERIAL PERMANENTE | P8: MÁQUINAS, UTENSÍLIOS E EQUIPAMENTOS DIVERSOS | Q8: Sistema de Climatização - Materiais | R8: 10000 | S8: Não tem o Cód. na LDO
A9: 06 | B9: 001 | C9: 04 | D9: 122 | E9: 0001 | F9: 2.011 | G9: 4.4.90.52.00 | H9: 06.001.04.122.0001.2.011.4.4.90.52.00 | I9: 06 - SECRETARIA DE ADMINISTRAÇÃO | J9: 001-GABINETE DA SECRETARIA DE ADMINISTRAÇÃO | K9: 4-ADMINISTRAÇÃO | L9: 122-ADMINISTRAÇÃO GERAL | M9: 0001-Administração e Coordenação Geral​ | N9: 2.011-Manutenção de Equipamentos Públicos | O9: 4.4.90.52.00-EQUIPAMENTOS E MATERIAL PERMANENTE | P9: OUTROS MATERIAIS PERMANENTES | R9: 100000 | S9: Não tem o Cód. na LDO
A10: 06 | B10: 001 | C10: 04 | D10: 122 | E10: 0001 | F10: 2.011 | G10: 3.3.90.92.00 | H10: 06.001.04.122.0001.2.011.3.3.90.92.00 | I10: 06 - SECRETARIA DE ADMINISTRAÇÃO | J10: 001-GABINETE DA SECRETARIA DE ADMINISTRAÇÃO | K10: 4-ADMINISTRAÇÃO | L10: 122-ADMINISTRAÇÃO GERAL | M10: 0001-Administração e Coordenação Geral​ | N10: 2.011-Manutenção de Equipamentos Públicos | O10: 3.3.90.92.00-DESPESAS DE EXERCÍCIOS ANTERIORES | P10: OUTROS SERVIÇOS DE TERCEIROS - PESSOA JURÍDICA | R10: 1 | S10: Não tem o Cód. na LDO
A11: 06 | B11: 001 | C11: 04 | D11: 122 | E11: 0001 | F11: 2.011 | G11: 3.3.90.93.00 | H11: 06.001.04.122.0001.2.011.3.3.90.93.00 | I11: 06 - SECRETARIA DE ADMINISTRAÇÃO | J11: 001-GABINETE DA SECRETARIA DE ADMINISTRAÇÃO | K11: 4-ADMINISTRAÇÃO | L11: 122-ADMINISTRAÇÃO GERAL | M11: 0001-Administração e Coordenação Geral​ | N11: 2.011-Manutenção de Equipamentos Públicos | O11: 3.3.90.93.00-INDENIZAÇÕES E RESTITUIÇÕES | R11: 1 | S11: Não tem o Cód. na LDO
A12: 06 | B12: 011 | C12: 04 | D12: 128 | E12: 0002 | F12: 2.003 | G12: 3.3.90.30.00 | H12: 06.011.04.128.0002.2.003.3.3.90.30.00 | I12: 06 - SECRETARIA DE ADMINISTRAÇÃO | J12: 011-FUNDO MUNICIPAL DE VALORIZAÇÃO DOS SERVIDORES | K12: 4-ADMINISTRAÇÃO | L12: 128-FORMAÇÃO DE RECURSOS HUMANOS | M12: 0002-Governo Inteligente, Aberto e Inovador​ | N12: 2.003-Qualificação de Servidores e Processos Institucionais | O12: 3.3.90.30.00-MATERIAL DE CONSUMO | P12: MATERIAL DE EXPEDIENTE | R12: 100000 | S12: Não tem o Cód. na LDO
A13: 06 | B13: 011 | C13: 04 | D13: 128 | E13: 0002 | F13: 2.003 | G13: 3.3.90.40.00 | H13: 06.011.04.128.0002.2.003.3.3.90.40.00 | I13: 06 - SECRETARIA DE ADMINISTRAÇÃO | J13: 011-FUNDO MUNICIPAL DE VALORIZAÇÃO DOS SERVIDORES | K13: 4-ADMINISTRAÇÃO | L13: 128-FORMAÇÃO DE RECURSOS HUMANOS | M13: 0002-Governo Inteligente, Aberto e Inovador​ | N13: 2.003-Qualificação de Servidores e Processos Institucionais | O13: 3.3.90.40.00-SERVIÇOS DE TECNOLOGIA DA INFORMAÇÃO E COMUNICAÇÃO - PESSOA JURÍDICA | P13: OUTROS SERVIÇOS DE TECNOLOGIA DA INFORMAÇÃO E COMUNICAÇÃO - PESSOA JURÍDICA | R13: 100000 | S13: Não tem o Cód. na LDO
A14: 06 | B14: 011 | C14: 04 | D14: 128 | E14: 0002 | F14: 2.003 | G14: 4.4.90.52.00 | H14: 06.011.04.128.0002.2.003.4.4.90.52.00 | I14: 06 - SECRETARIA DE ADMINISTRAÇÃO | J14: 011-FUNDO MUNICIPAL DE VALORIZAÇÃO DOS SERVIDORES | K14: 4-ADMINISTRAÇÃO | L14: 128-FORMAÇÃO DE RECURSOS HUMANOS | M14: 0002-Governo Inteligente, Aberto e Inovador​ | N14: 2.003-Qualificação de Servidores e Processos Institucionais | O14: 4.4.90.52.00-EQUIPAMENTOS E MATERIAL PERMANENTE | P14: MÁQUINAS, UTENSÍLIOS E EQUIPAMENTOS DIVERSOS | R14: 100000 | S14: Não tem o Cód. na LDO
A15: 07 | B15: 001 | C15: 04 | D15: 122 | E15: 0002 | F15: 2.003 | G15: 3.3.90.36.00 | H15: 07.001.04.122.0002.2.003.3.3.90.36.00 | I15: 07 - SECRETARIA DE EMPREGO, TRABALHO E RENDA | J15: 001-GABINETE DA SECRETARIA DE EMPREGO, TRABALHO E RENDA | K15: 4-ADMINISTRAÇÃO | L15: 122-ADMINISTRAÇÃO GERAL | M15: 0002-Governo Inteligente, Aberto e Inovador​ | N15: 2.003-Qualificação de Servidores e Processos Institucionais | O15: 3.3.90.36.00-OUTROS SERVIÇOS DE TERCEIROS - PESSOA FÍSICA | Q15: 90 | R15: 1 | S15: Não tem o Cód. na LDO
A16: 07 | B16: 001 | C16: 04 | D16: 122 | E16: 0002 | F16: 2.003 | G16: 3.3.90.39.00 | H16: 07.001.04.122.0002.2.003.3.3.90.39.00 | I16: 07 - SECRETARIA DE EMPREGO, TRABALHO E RENDA | J16: 001-GABINETE DA SECRETARIA DE EMPREGO, TRABALHO E RENDA | K16: 4-ADMINISTRAÇÃO | L16: 122-ADMINISTRAÇÃO GERAL | M16: 0002-Governo Inteligente, Aberto e Inovador​ | N16: 2.003-Qualificação de Servidores e Processos Institucionais | O16: 3.3.90.39.00-OUTROS SERVIÇOS DE TERCEIROS - PESSOA JURÍDICA | P16: OUTROS SERVIÇOS DE TERCEIRO PESSOA JURÍDICA - PAGAMENTO ANTECIPADO | Q16: 91 | R16: 1 | S16: Não tem o Cód. na LDO
A17: 07 | B17: 001 | C17: 04 | D17: 122 | E17: 0002 | F17: 2.005 | G17: 3.3.90.30.00 | H17: 07.001.04.122.0002.2.005.3.3.90.30.00 | I17: 07 - SECRETARIA DE EMPREGO, TRABALHO E RENDA | J17: 001-GABINETE DA SECRETARIA DE EMPREGO, TRABALHO E RENDA | K17: 4-ADMINISTRAÇÃO | L17: 122-ADMINISTRAÇÃO GERAL | M17: 0002-Governo Inteligente, Aberto e Inovador​ | N17: 2.005-Promoção de Eventos, Comunicação e Participação Social | O17: 3.3.90.30.00-MATERIAL DE CONSUMO | P17: GÊNEROS DE ALIMENTAÇÃO | Q17: 92 | S17: Não tem o Cód. na LDO
A18: 07 | B18: 001 | C18: 04 | D18: 122 | E18: 0002 | F18: 2.005 | G18: 3.3.90.39.00 | H18: 07.001.04.122.0002.2.005.3.3.90.39.00 | I18: 07 - SECRETARIA DE EMPREGO, TRABALHO E RENDA | J18: 001-GABINETE DA SECRETARIA DE EMPREGO, TRABALHO E RENDA | K18: 4-ADMINISTRAÇÃO | L18: 122-ADMINISTRAÇÃO GERAL | M18: 0002-Governo Inteligente, Aberto e Inovador​ | N18: 2.005-Promoção de Eventos, Comunicação e Participação Social | O18: 3.3.90.39.00-OUTROS SERVIÇOS DE TERCEIROS - PESSOA JURÍDICA | P18: SERVIÇOS GRÁFICOS E EDITORIAIS | Q18: 93 | S18: Não tem o Cód. na LDO
A19: 07 | B19: 001 | C19: 11 | D19: 334 | E19: 0017 | F19: 1.002 | G19: 3.3.90.39.00 | H19: 07.001.11.334.0017.1.002.3.3.90.39.00 | I19: 07 - SECRETARIA DE EMPREGO, TRABALHO E RENDA | J19: 001-GABINETE DA SECRETARIA DE EMPREGO, TRABALHO E RENDA | K19: 11-TRABALHO | L19: 334-FOMENTO AO TRABALHO | M19: 0017-Trabalho, Emprego e Renda​ | N19: 1.002-Reforma e Ampliação de Unidades | O19: 3.3.90.39.00-OUTROS SERVIÇOS DE TERCEIROS - PESSOA JURÍDICA | P19: OUTROS SERVIÇOS DE TERCEIRO PESSOA JURÍDICA - PAGAMENTO ANTECIPADO | Q19: 94 | S19: Não tem o Cód. na LDO
A20: 07 | B20: 001 | C20: 11 | D20: 334 | E20: 0017 | F20: 2.011 | G20: 3.3.90.30.00 | H20: 07.001.11.334.0017.2.011.3.3.90.30.00 | I20: 07 - SECRETARIA DE EMPREGO, TRABALHO E RENDA | J20: 001-GABINETE DA SECRETARIA DE EMPREGO, TRABALHO E RENDA | K20: 11-TRABALHO | L20: 334-FOMENTO AO TRABALHO | M20: 0017-Trabalho, Emprego e Renda​ | N20: 2.011-Manutenção de Equipamentos Públicos | O20: 3.3.90.30.00-MATERIAL DE CONSUMO | P20: GÊNEROS DE ALIMENTAÇÃO | Q20: 95 | R20: 15000 | S20: Não tem o Cód. na LDO
A21: 07 | B21: 001 | C21: 11 | D21: 334 | E21: 0017 | F21: 2.011 | G21: 3.3.90.30.00 | H21: 07.001.11.334.0017.2.011.3.3.90.30.00 | I21: 07 - SECRETARIA DE EMPREGO, TRABALHO E RENDA | J21: 001-GABINETE DA SECRETARIA DE EMPREGO, TRABALHO E RENDA | K21: 11-TRABALHO | L21: 334-FOMENTO AO TRABALHO | M21: 0017-Trabalho, Emprego e Renda​ | N21: 2.011-Manutenção de Equipamentos Públicos | O21: 3.3.90.30.00-MATERIAL DE CONSUMO | P21: MATERIAL DE LIMPEZA E PRODUTOS DE HIGIENIZAÇÃO | Q21: 95 | R21: 60000 | S21: Não tem o Cód. na LDO
A22: 07 | B22: 001 | C22: 11 | D22: 334 | E22: 0017 | F22: 2.011 | G22: 3.3.90.30.00 | H22: 07.001.11.334.0017.2.011.3.3.90.30.00 | I22: 07 - SECRETARIA DE EMPREGO, TRABALHO E RENDA | J22: 001-GABINETE DA SECRETARIA DE EMPREGO, TRABALHO E RENDA | K22: 11-TRABALHO | L22: 334-FOMENTO AO TRABALHO | M22: 0017-Trabalho, Emprego e Renda​ | N22: 2.011-Manutenção de Equipamentos Públicos | O22: 3.3.90.30.00-MATERIAL DE CONSUMO | P22: MATERIAL DE EXPEDIENTE | Q22: 95 | R22: 50000 | S22: Não tem o Cód. na LDO
A23: 07 | B23: 001 | C23: 11 | D23: 334 | E23: 0017 | F23: 2.011 | G23: 3.3.90.30.00 | H23: 07.001.11.334.0017.2.011.3.3.90.30.00 | I23: 07 - SECRETARIA DE EMPREGO, TRABALHO E RENDA | J23: 001-GABINETE DA SECRETARIA DE EMPREGO, TRABALHO E RENDA | K23: 11-TRABALHO | L23: 334-FOMENTO AO TRABALHO | M23: 0017-Trabalho, Emprego e Renda​ | N23: 2.011-Manutenção de Equipamentos Públicos | O23: 3.3.90.30.00-MATERIAL DE CONSUMO | P23: MATERIAL DE COPA E COZINHA | Q23: 95 | R23: 40000 | S23: Não tem o Cód. na LDO
A24: 07 | B24: 001 | C24: 11 | D24: 334 | E24: 0017 | F24: 2.011 | G24: 3.3.90.30.00 | H24: 07.001.11.334.0017.2.011.3.3.90.30.00 | I24: 07 - SECRETARIA DE EMPREGO, TRABALHO E RENDA | J24: 001-GABINETE DA SECRETARIA DE EMPREGO, TRABALHO E RENDA | K24: 11-TRABALHO | L24: 334-FOMENTO AO TRABALHO | M24: 0017-Trabalho, Emprego e Renda​ | N24: 2.011-Manutenção de Equipamentos Públicos | O24: 3.3.90.30.00-MATERIAL DE CONSUMO | P24: MATERIAL ELÉTRICO E ELETRÔNICO | Q24: 95 | R24: 15000 | S24: Não tem o Cód. na LDO
A25: 07 | B25: 001 | C25: 11 | D25: 334 | E25: 0017 | F25: 2.011 | G25: 3.3.90.39.00 | H25: 07.001.11.334.0017.2.011.3.3.90.39.00 | I25: 07 - SECRETARIA DE EMPREGO, TRABALHO E RENDA | J25: 001-GABINETE DA SECRETARIA DE EMPREGO, TRABALHO E RENDA | K25: 11-TRABALHO | L25: 334-FOMENTO AO TRABALHO | M25: 0017-Trabalho, Emprego e Renda​ | N25: 2.011-Manutenção de Equipamentos Públicos | O25: 3.3.90.39.00-OUTROS SERVIÇOS DE TERCEIROS - PESSOA JURÍDICA | P25: SERVIÇOS GRÁFICOS E EDITORIAIS | Q25: 0 | R25: 80000 | S25: Não tem o Cód. na LDO
A26: 07 | B26: 001 | C26: 11 | D26: 334 | E26: 0017 | F26: 2.011 | G26: 3.3.90.39.00 | H26: 07.001.11.334.0017.2.011.3.3.90.39.00 | I26: 07 - SECRETARIA DE EMPREGO, TRABALHO E RENDA | J26: 001-GABINETE DA SECRETARIA DE EMPREGO, TRABALHO E RENDA | K26: 11-TRABALHO | L26: 334-FOMENTO AO TRABALHO | M26: 0017-Trabalho, Emprego e Renda​ | N26: 2.011-Manutenção de Equipamentos Públicos | O26: 3.3.90.39.00-OUTROS SERVIÇOS DE TERCEIROS - PESSOA JURÍDICA | P26: OUTROS SERVIÇOS DE TERCEIRO PESSOA JURÍDICA - PAGAMENTO ANTECIPADO | Q26: 0 | R26: 120000 | S26: Não tem o Cód. na LDO
A27: 07 | B27: 001 | C27: 11 | D27: 334 | E27: 0017 | F27: 2.011 | G27: 4.4.90.52.00 | H27: 07.001.11.334.0017.2.011.4.4.90.52.00 | I27: 07 - SECRETARIA DE EMPREGO, TRABALHO E RENDA | J27: 001-GABINETE DA SECRETARIA DE EMPREGO, TRABALHO E RENDA | K27: 11-TRABALHO | L27: 334-FOMENTO AO TRABALHO | M27: 0017-Trabalho, Emprego e Renda​ | N27: 2.011-Manutenção de Equipamentos Públicos | O27: 4.4.90.52.00-EQUIPAMENTOS E MATERIAL PERMANENTE | P27: APARELHOS E UTENSÍLIOS DOMÉSTICOS | Q27: 0 | R27: 35000 | S27: Não tem o Cód. na LDO
